Workbook

Sheet data
A1: Month | B1: User | C1: Bike | D1: Rides
A2: 45870 | B2: casual | C2: classic | D2: 118087
A3: 45870 | B3: casual | C3: electric | D3: 219651
A4: 45870 | B4: member | C4: classic | D4: 162894
A5: 45870 | B5: member | C5: electric | D5: 289545
A6: 45870 | B6: total | D6: 790177
A7: 45901 | B7: casual | C7: classic | D7: 81295
A8: 45901 | B8: casual | C8: electric | D8: 184166
A9: 45901 | B9: member | C9: classic | D9: 158034
A10: 45901 | B10: member | C10: electric | D10: 291264
A11: 45901 | B11: total | D11: =SUM(D7:D10) -> 714759
A12: 45931 | B12: casual | C12: classic | D12: 66625
A13: 45931 | B13: casual | C13: electric | D13: 157385
A14: 45931 | B14: member | C14: classic | D14: 143303
A15: 45931 | B15: member | C15: electric | D15: 278726
A16: 45931 | B16: total | D16: =SUM(D12:D15) -> 646039
A17: 45962 | B17: casual | C17: classic | D17: 27304
A18: 45962 | B18: casual | C18: electric | D18: 71836
A19: 45962 | B19: member | C19: classic | D19: 88146
A20: 45962 | B20: member | C20: electric | D20: 169313
A21: 45962 | B21: total | D21: =SUM(D17:D20) -> 356599
A22: 45992 | B22: casual | C22: classic | D22: 7037
A23: 45992 | B23: casual | C23: electric | D23: 21043
A24: 45992 | B24: member | C24: classic | D24: 37823
A25: 45992 | B25: member | C25: electric | D25: 74631
A26: 45992 | B26: total | D26: =SUM(D22:D25) -> 140534
A27: 46023 | B27: casual | C27: classic | D27: 5908
A28: 46023 | B28: casual | C28: electric | D28: 18841
A29: 46023 | B29: member | C29: classic | D29: 38065
A30: 46023 | B30: member | C30: electric | D30: 74973
A31: 46023 | B31: total | D31: =SUM(D27:D30) -> 137787
A32: 46054 | B32: casual | C32: classic | D32: 11619
A33: 46054 | B33: casual | C33: electric | D33: 29554
A34: 46054 | B34: member | C34: classic | D34: 55271
A35: 46054 | B35: member | C35: electric | D35: 105006
A36: 46054 | B36: total | D36: =SUM(D32:D35) -> 201450
A37: 46082 | B37: casual | C37: classic | D37: 23889
A38: 46082 | B38: casual | C38: electric | D38: 63967
A39: 46082 | B39: member | C39: classic | D39: 72213
A40: 46082 | B40: member | C40: electric | D40: 156968
...

Sheet summary&visuals
A1: Month | B1: Group | C1: Total Rides
A2: 45870 | B2: casual | C2: =data!D2+data!D3 -> 337738
A3: 45870 | B3: member | C3: =data!D4+data!D5 -> 452439
A4: 45901 | B4: casual | C4: =data!D7+data!D8 -> 265461
A5: 45901 | B5: member | C5: =data!D9+data!D10 -> 449298
A6: 45931 | B6: casual | C6: =data!D12+data!D13 -> 224010
A7: 45931 | B7: member | C7: =data!D14+data!D15 -> 422029
A8: 45962 | B8: casual | C8: =data!D17+data!D18 -> 99140
A9: 45962 | B9: member | C9: =data!D19+data!D20 -> 257459
A10: 45992 | B10: casual | C10: =data!D22+data!D23 -> 28080
A11: 45992 | B11: member | C11: =data!D24+data!D25 -> 112454
A12: 46023 | B12: casual | C12: =data!D27+data!D28 -> 24749
A13: 46023 | B13: member | C13: =data!D29+data!D30 -> 113038
A14: 46054 | B14: casual | C14: =data!D32+data!D33 -> 41173
A15: 46054 | B15: member | C15: =data!D34+data!D35 -> 160277
A16: 46082 | B16: casual | C16: =data!D37+data!D38 -> 87856
A17: 46082 | B17: member | C17: =data!D39+data!D40 -> 229181
A18: 46113 | B18: casual | C18: =data!D42+data!D43 -> 131514
A19: 46113 | B19: member | C19: =data!D44+data!D45 -> 316738
A20: 46143 | B20: casual | C20: =data!D47+data!D48 -> 245105
A21: 46143 | B21: member | C21: =data!D49+data!D50 -> 408599
A22: 46174 | B22: casual | C22: =data!D52+data!D53 -> 308462
A23: 46174 | B23: member | C23: =data!D54+data!D55 -> 454088
A24: 46204 | B24: casual | C24: =data!D57+data!D58 -> 357756
A25: 46204 | B25: member | C25: =data!D59+data!D60 -> 511295
